Workbook

Sheet 종합Sheet
D1: =COUNTIF(D4:D157,"발주") -> 2 | I1: Round | J1: 1R | K1: 2R | L1: 3R | M1: 4R | N1: 5R | O1: 6R | P1: 7R | Q1: 8R | R1: 9R | S1: 10R | T1: 11R | U1: 12R | V1: 13R | W1: 14R | X1: 15R | Y1: 16R | Z1: 17R | AA1: 18R | AB1: 19R | AC1: 20R | AD1: 21R | AE1: 22R | AF1: 23R | AG1: 24R | AH1: 25R | AI1: 26R | AJ1: 27R | AK1: 28R | AL1: 29R | AM1: 30R | AN1: 31R | AO1: 32R | AP1: 33R | AQ1: 34R | AR1: 35R | AS1: 36R | AT1: 37R | AU1: 38R | AV1: 39R | AW1: 40R | AX1: 41R | AY1: 42R | AZ1: 43R | BA1: 44R | BB1: 45R | BC1: 46R | BD1: 47R | BE1: 48R | BF1: 49R | BG1: 50R
D2: =COUNTIF(D4:D157,"지급") -> 74 | E2: =COUNTIF(E4:E140,"지급") -> 0 | H2: =SUM(J2:AR2)/COUNTA(J2:BB2) -> 17.488889 | I2: Check | J2: =COUNTA(J4:J152) -> 14 | K2: =COUNTA(K4:K152) -> 30 | L2: =COUNTA(L4:L152) -> 17 | M2: =COUNTA(M4:M152) -> 20 | N2: =COUNTA(N4:N152) -> 22 | O2: =COUNTA(O4:O152) -> 18 | P2: =COUNTA(P4:P152) -> 12 | Q2: =COUNTA(Q4:Q152) -> 33 | ... BG2: =COUNTA(BG4:BG152) -> 0
A3: 인원 | B3: 이름 | C3: 입단년도 | D3: 유니폼 | E3: 바람막이 | F3: 카톡 | G3: Rank | H3: 종합 Point | I3: 출전 Point | J3: 46076 | K3: 46079 | L3: 46085 | M3: 46086 | N3: 46094 | O3: 46096 | P3: 46097 | Q3: 46100 | R3: 46107 | S3: 46114 | T3: 46121 | U3: 46128 | V3: 46133 | W3: 46149 | X3: 46153 | Y3: 46156 | Z3: 46170 | AA3: 46177 | AB3: 46184 | AC3: 46191 | AD3: 46198 | AE3: 46202 | AF3: 46205 | AG3: 46212 | AH3: 46219 | AI3: 46233 | AJ3: 46240 | AK3: 46246 | AL3: 46254 | AM3: 46261 | AN3: 46265 | AO3: 46275 | AP3: 46282 | AQ3: 46296 | AR3: 46303 | AS3: 46310
A4: 1 | B4: 김인혁 | C4: Origin | D4: 지급 | F4: ○ | G4: =RANK(H4,$H$4:$H$122,0) -> 4 | H4: =I4+개인기록Sheet!C4 -> 28.6 | I4: =(COUNTIF(J4:CD4,"출전")*1) -> 26 | J4: 출전 | M4: 출전 | N4: 출전 | O4: 출전 | P4: 출전 | Q4: 출전 | R4: 출전 | S4: 출전 | T4: 출전 | U4: 출전 | V4: 출전 | W4: 출전 | Y4: 출전 | AA4: 출전 | AB4: 출전 | AC4: 출전 | AE4: 출전 | AF4: 출전 | AG4: 출전 | AJ4: 출전 | AK4: 출전 | AL4: 출전 | AP4: 출전 | AQ4: 출전 | AR4: 출전 | AS4: 출전
A5: 2 | B5: 신재경 | C5: 2021 | D5: 지급 | F5: ○ | G5: =RANK(H5,$H$4:$H$122,0) -> 55 | H5: =I5+개인기록Sheet!C5 -> 6.9 | I5: =(COUNTIF(J5:CD5,"출전")*1) -> 6 | L5: 출전 | U5: 출전 | AC5: 출전 | AG5: 출전 | AI5: 출전 | AO5: 출전
A6: 3 | B6: 정효태 | C6: Origin | D6: 발주 | F6: ○ | G6: =RANK(H6,$H$4:$H$122,0) -> 92 | H6: =I6+개인기록Sheet!C6 -> 0 | I6: =(COUNTIF(J6:CD6,"출전")*1) -> 0
A7: 4 | B7: 이승민 | C7: Origin | D7: =COUNTA(AF7:AU7) -> 0 | F7: ○ | G7: =RANK(H7,$H$4:$H$122,0) -> 92 | H7: =I7+개인기록Sheet!C7 -> 0 | I7: =(COUNTIF(J7:CD7,"출전")*1) -> 0
A8: 5 | B8: 이정석 | C8: Origin | D8: 지급 | F8: ○ | G8: =RANK(H8,$H$4:$H$122,0) -> 92 | H8: =I8+개인기록Sheet!C8 -> 0 | I8: =(COUNTIF(J8:CD8,"출전")*1) -> 0
A9: 6 | B9: 강종찬 | C9: Origin | D9: 지급 | F9: ○ | G9: =RANK(H9,$H$4:$H$122,0) -> 45 | H9: =I9+개인기록Sheet!C9 -> 9 | I9: =(COUNTIF(J9:CD9,"출전")*1) -> 8 | K9: 출전 | O9: 출전 | Q9: 출전 | U9: 출전 | AA9: 출전 | AL9: 출전 | AM9: 출전 | AQ9: 출전
A10: 7 | B10: 강관석 | C10: 2024 | D10: 지급 | F10: ○ | G10: =RANK(H10,$H$4:$H$122,0) -> 15 | H10: =I10+개인기록Sheet!C10 -> 20.6 | I10: =(COUNTIF(J10:CD10,"출전")*1) -> 17 | J10: 출전 | N10: 출전 | Q10: 출전 | S10: 출전 | T10: 출전 | W10: 출전 | Y10: 출전 | Z10: 출전 | AA10: 출전 | AC10: 출전 | AD10: 출전 | AF10: 출전 | AG10: 출전 | AH10: 출전 | AI10: 출전 | AL10: 출전 | AO10: 출전
A11: 8 | B11: 강기혁 | C11: 2022 | D11: 지급 | F11: ○ | G11: =RANK(H11,$H$4:$H$122,0) -> 12 | H11: =I11+개인기록Sheet!C11 -> 21.6 | I11: =(COUNTIF(J11:CD11,"출전")*1) -> 16 | J11: 출전 | L11: 출전 | M11: 출전 | Q11: 출전 | U11: 출전 | V11: 출전 | Y11: 출전 | AA11: 출전 | AB11: 출전 | AC11: 출전 | AH11: 출전 | AM11: 출전 | AO11: 출전 | AP11: 출전 | AQ11: 출전 | AR11: 출전
A12: 9 | B12: 강도일 | C12: 2025 | D12: =COUNTA(AF12:AU12) -> 0 | F12: ○ | G12: =RANK(H12,$H$4:$H$122,0) -> 86 | H12: =I12+개인기록Sheet!C12 -> 1 | I12: =(COUNTIF(J12:CD12,"출전")*1) -> 1 | Q12: 출전
A13: 10 | B13: 강일수 | C13: 2022 | D13: =COUNTA(AF13:AU13) -> 0 | F13: ○ | G13: =RANK(H13,$H$4:$H$122,0) -> 92 | H13: =I13+개인기록Sheet!C13 -> 0 | I13: =(COUNTIF(J13:CD13,"출전")*1) -> 0
A14: 11 | B14: 구교훈 | C14: Origin | D14: =COUNTA(AF14:AU14) -> 0 | F14: ○ | G14: =RANK(H14,$H$4:$H$122,0) -> 92 | H14: =I14+개인기록Sheet!C14 -> 0 | I14: =(COUNTIF(J14:CD14,"출전")*1) -> 0
A15: 12 | B15: 권민강 | C15: 2026 | D15: =COUNTA(AF15:AU15) -> 4 | F15: ○ | G15: =RANK(H15,$H$4:$H$122,0) -> 67 | H15: =I15+개인기록Sheet!C15 -> 4.6 | I15: =(COUNTIF(J15:CD15,"출전")*1) -> 4 | AG15: 출전 | AN15: 출전 | AO15: 출전 | AP15: 출전
A16: 13 | B16: 김기문 | C16: 2022 | D16: 지급 | F16: ○ | G16: =RANK(H16,$H$4:$H$122,0) -> 30 | H16: =I16+개인기록Sheet!C16 -> 13.8 | I16: =(COUNTIF(J16:CD16,"출전")*1) -> 10 | K16: 출전 | L16: 출전 | O16: 출전 | W16: 출전 | X16: 출전 | AF16: 출전 | AG16: 출전 | AK16: 출전 | AM16: 출전 | AR16: 출전
A17: 14 | B17: 김기태 | C17: 2026 | D17: 지급 | F17: ○ | G17: =RANK(H17,$H$4:$H$122,0) -> 17 | H17: =I17+개인기록Sheet!C17 -> 18.8 | I17: =(COUNTIF(J17:CD17,"출전")*1) -> 15 | K17: 출전 | N17: 출전 | P17: 출전 | Q17: 출전 | R17: 출전 | S17: 출전 | U17: 출전 | W17: 출전 | X17: 출전 | Z17: 출전 | AA17: 출전 | AB17: 출전 | AF17: 출전 | AG17: 출전 | AJ17: 출전
A18: 15 | B18: 김덕준 | C18: 2023 | D18: 지급 | F18: ○ | G18: =RANK(H18,$H$4:$H$122,0) -> 92 | H18: =I18+개인기록Sheet!C18 -> 0 | I18: =(COUNTIF(J18:CD18,"출전")*1) -> 0
A19: 16 | B19: 김도원 | C19: 2026 | D19: =COUNTA(AF19:AU19) -> 1 | F19: ○ | G19: =RANK(H19,$H$4:$H$122,0) -> 86 | H19: =I19+개인기록Sheet!C19 -> 1 | I19: =(COUNTIF(J19:CD19,"출전")*1) -> 1 | AO19: 출전
A20: 17 | B20: 김민섭 | C20: 2023 | D20: 지급 | F20: ○ | G20: =RANK(H20,$H$4:$H$122,0) -> 61 | H20: =I20+개인기록Sheet!C20 -> 5.4 | I20: =(COUNTIF(J20:CD20,"출전")*1) -> 5 | K20: 출전 | O20: 출전 | Q20: 출전 | AI20: 출전 | AK20: 출전
A21: 18 | B21: 김민찬 | C21: 2024 | D21: =COUNTA(AF21:AU21) -> 0 | F21: ○ | G21: =RANK(H21,$H$4:$H$122,0) -> 92 | H21: =I21+개인기록Sheet!C21 -> 0 | I21: =(COUNTIF(J21:CD21,"출전")*1) -> 0
A22: 19 | B22: 김범기 | C22: 2022 | D22: =COUNTA(AF22:AU22) -> 0 | F22: ○ | G22: =RANK(H22,$H$4:$H$122,0) -> 92 | H22: =I22+개인기록Sheet!C22 -> 0 | I22: =(COUNTIF(J22:CD22,"출전")*1) -> 0
A23: 20 | B23: 김병준 | C23: 2024 | D23: 지급 | F23: ○ | G23: =RANK(H23,$H$4:$H$122,0) -> 86 | H23: =I23+개인기록Sheet!C23 -> 1 | I23: =(COUNTIF(J23:CD23,"출전")*1) -> 1 | S23: 출전
A24: 21 | B24: 김부건 | C24: Origin | D24: 지급 | F24: ○ | G24: =RANK(H24,$H$4:$H$122,0) -> 44 | H24: =I24+개인기록Sheet!C24 -> 9.3 | I24: =(COUNTIF(J24:CD24,"출전")*1) -> 8 | L24: 출전 | Y24: 출전 | Z24: 출전 | AB24: 출전 | AM24: 출전 | AN24: 출전 | AO24: 출전 | AS24: 출전
A25: 22 | B25: 김성수 | C25: 2023 | D25: 지급 | F25: ○ | G25: =RANK(H25,$H$4:$H$122,0) -> 25 | H25: =I25+개인기록Sheet!C25 -> 15.9 | I25: =(COUNTIF(J25:CD25,"출전")*1) -> 13 | K25: 출전 | L25: 출전 | S25: 출전 | U25: 출전 | X25: 출전 | AC25: 출전 | AE25: 출전 | AI25: 출전 | AJ25: 출전 | AK25: 출전 | AO25: 출전 | AP25: 출전 | AS25: 출전
A26: 23 | B26: 김성준 | C26: 2024 | D26: 지급 | F26: ○ | G26: =RANK(H26,$H$4:$H$122,0) -> 1 | H26: =I26+개인기록Sheet!C26 -> 37.7 | I26: =(COUNTIF(J26:CD26,"출전")*1) -> 27 | K26: 출전 | L26: 출전 | M26: 출전 | N26: 출전 | P26: 출전 | Q26: 출전 | R26: 출전 | S26: 출전 | U26: 출전 | V26: 출전 | W26: 출전 | X26: 출전 | Z26: 출전 | AA26: 출전 | AC26: 출전 | AD26: 출전 | AF26: 출전 | AG26: 출전 | AH26: 출전 | AI26: 출전 | AJ26: 출전 | AK26: 출전 | AL26: 출전 | AM26: 출전 | AN26: 출전 | AO26: 출전 | AR26: 출전
A27: 24 | B27: 김송환 | C27: Origin | D27: 지급 | F27: ○ | G27: =RANK(H27,$H$4:$H$122,0) -> 32 | H27: =I27+개인기록Sheet!C27 -> 13.1 | I27: =(COUNTIF(J27:CD27,"출전")*1) -> 10 | L27: 출전 | N27: 출전 | U27: 출전 | W27: 출전 | AA27: 출전 | AJ27: 출전 | AK27: 출전 | AM27: 출전 | AN27: 출전 | AO27: 출전
A28: 25 | B28: 김영태 | C28: 2023 | D28: =COUNTA(AF28:AU28) -> 0 | F28: ○ | G28: =RANK(H28,$H$4:$H$122,0) -> 92 | H28: =I28+개인기록Sheet!C28 -> 0 | I28: =(COUNTIF(J28:CD28,"출전")*1) -> 0
A29: 26 | B29: 김용빈 | C29: 2023 | D29: 지급 | F29: ○ | G29: =RANK(H29,$H$4:$H$122,0) -> 75 | H29: =I29+개인기록Sheet!C29 -> 3 | I29: =(COUNTIF(J29:CD29,"출전")*1) -> 3 | K29: 출전 | M29: 출전 | Q29: 출전
A30: 27 | B30: 김용현 | C30: Origin | D30: 지급 | F30: ○ | G30: =RANK(H30,$H$4:$H$122,0) -> 16 | H30: =I30+개인기록Sheet!C30 -> 19.6 | I30: =(COUNTIF(J30:CD30,"출전")*1) -> 15 | K30: 출전 | L30: 출전 | N30: 출전 | Q30: 출전 | S30: 출전 | T30: 출전 | Y30: 출전 | AC30: 출전 | AF30: 출전 | AG30: 출전 | AH30: 출전 | AJ30: 출전 | AM30: 출전 | AP30: 출전 | AS30: 출전
A31: 28 | B31: 김우인 | C31: 2023 | D31: 지급 | F31: ○ | G31: =RANK(H31,$H$4:$H$122,0) -> 2 | H31: =I31+개인기록Sheet!C31 -> 32.6 | I31: =(COUNTIF(J31:CD31,"출전")*1) -> 27 | J31: 출전 | K31: 출전 | M31: 출전 | N31: 출전 | O31: 출전 | R31: 출전 | S31: 출전 | U31: 출전 | W31: 출전 | Y31: 출전 | Z31: 출전 | AB31: 출전 | AC31: 출전 | AD31: 출전 | AF31: 출전 | AG31: 출전 | AH31: 출전 | AI31: 출전 | AJ31: 출전 | AK31: 출전 | AL31: 출전 | AM31: 출전 | AO31: 출전 | AP31: 출전 | AQ31: 출전 | AR31: 출전 | AS31: 출전
A32: 29 | B32: 김종준 | C32: Origin | D32: 지급 | F32: ○ | G32: =RANK(H32,$H$4:$H$122,0) -> 37 | H32: =I32+개인기록Sheet!C32 -> 11.4 | I32: =(COUNTIF(J32:CD32,"출전")*1) -> 11 | K32: 출전 | L32: 출전 | M32: 출전 | N32: 출전 | O32: 출전 | Y32: 출전 | AC32: 출전 | AG32: 출전 | AI32: 출전 | AQ32: 출전 | AS32: 출전
A33: 30 | B33: 김종혁 | C33: 2025 | D33: 지급 | F33: ○ | G33: =RANK(H33,$H$4:$H$122,0) -> 9 | H33: =I33+개인기록Sheet!C33 -> 23.6 | I33: =(COUNTIF(J33:CD33,"출전")*1) -> 19 | K33: 출전 | M33: 출전 | N33: 출전 | O33: 출전 | P33: 출전 | Q33: 출전 | Z33: 출전 | AB33: 출전 | AE33: 출전 | AF33: 출전 | AG33: 출전 | AH33: 출전 | AI33: 출전 | AJ33: 출전 | AK33: 출전 | AL33: 출전 | AN33: 출전 | AQ33: 출전 | AR33: 출전
A34: 31 | B34: 김진형 | C34: 2025 | D34: =COUNTA(AF34:AU34) -> 0 | F34: ○ | G34: =RANK(H34,$H$4:$H$122,0) -> 92 | H34: =I34+개인기록Sheet!C34 -> 0 | I34: =(COUNTIF(J34:CD34,"출전")*1) -> 0
A35: 32 | B35: 김진호 | C35: 2025 | D35: 지급 | F35: ○ | G35: =RANK(H35,$H$4:$H$122,0) -> 6 | H35: =I35+개인기록Sheet!C35 -> 27.2 | I35: =(COUNTIF(J35:CD35,"출전")*1) -> 20 | K35: 출전 | L35: 출전 | N35: 출전 | Q35: 출전 | S35: 출전 | U35: 출전 | W35: 출전 | X35: 출전 | Z35: 출전 | AA35: 출전 | AB35: 출전 | AC35: 출전 | AH35: 출전 | AI35: 출전 | AJ35: 출전 | AK35: 출전 | AM35: 출전 | AO35: 출전 | AP35: 출전 | AR35: 출전
A36: 33 | B36: 김태성 | C36: 2023 | D36: 지급 | F36: ○ | G36: =RANK(H36,$H$4:$H$122,0) -> 46 | H36: =I36+개인기록Sheet!C36 -> 8.6 | I36: =(COUNTIF(J36:CD36,"출전")*1) -> 8 | K36: 출전 | N36: 출전 | U36: 출전 | Z36: 출전 | AE36: 출전 | AI36: 출전 | AL36: 출전 | AR36: 출전
A37: 34 | B37: 김태양 | C37: 2025 | D37: =COUNTA(AF37:AU37) -> 0 | F37: ○ | G37: =RANK(H37,$H$4:$H$122,0) -> 92 | H37: =I37+개인기록Sheet!C37 -> 0 | I37: =(COUNTIF(J37:CD37,"출전")*1) -> 0
A38: 35 | B38: 김태완 | C38: 2025 | D38: 지급 | F38: ○ | G38: =RANK(H38,$H$4:$H$122,0) -> 78 | H38: =I38+개인기록Sheet!C38 -> 2.4 | I38: =(COUNTIF(J38:CD38,"출전")*1) -> 2 | Q38: 출전 | AI38: 출전
A39: 36 | B39: 김태호 | C39: Origin | D39: =COUNTA(AF39:AU39) -> 0 | F39: ○ | G39: =RANK(H39,$H$4:$H$122,0) -> 92 | H39: =I39+개인기록Sheet!C39 -> 0 | I39: =(COUNTIF(J39:CD39,"출전")*1) -> 0
A40: 37 | B40: 김현우 | C40: 2024 | D40: =COUNTA(AF40:AU40) -> 0 | F40: ○ | G40: =RANK(H40,$H$4:$H$122,0) -> 92 | H40: =I40+개인기록Sheet!C40 -> 0 | I40: =(COUNTIF(J40:CD40,"출전")*1) -> 0
...

Sheet 경기기록Sheet
B2: 46094 | C2: Home | D2: Away | E2: Goal | I2: Assist | M2: Balance | Q2: Clean Sheet
B3: 1Q | C3: 3 | D3: 0 | E3: 강기혁 | F3: 김진호 | G3: 김우인 | I3: 오우영 | J3: 김용현 | K3: 김진호 | M3: 김용현 | N3: 오우영 | O3: 강기혁 | Q3: 유상근 | R3: 김성준 | S3: 정민수 | T3: 조현우 | V3: 김송환
B5: 2Q | C5: 1 | D5: 0 | E5: 한상규 | I5: 김종혁 | M5: 김송환 | N5: 강관석 | O5: 조진한 | Q5: 노민준 | R5: 차승원 | S5: 황석원 | T5: 한상규 | V5: 김우인
B7: 3Q | C7: 2 | D7: 0 | E7: 이상민 | F7: 강기혁 | I7: 노민준 | J7: 오우영 | M7: 오우영 | N7: 강기혁 | O7: 김용현 | Q7: 유상근 | R7: 이상민 | S7: 노민준 | T7: 홍현석 | V7: 김우인
B9: 4Q | C9: 2 | D9: 0 | E9: 김우인 | F9: 김성준 | I9: 김성준 | J9: 조진한 | M9: 김송환 | N9: 김성준 | O9: 조진한 | Q9: 한상규 | R9: 차승원 | S9: 황석원 | T9: 조현우 | V9: 유상근
B11: Total | C11: =SUM(C3:C10) -> 8 | D11: =SUM(D3:D10) -> 0
B13: 46097 | C13: 김청축 | D13: CT24 | E13: Goal | I13: Assist | M13: Balance | Q13: Clean Sheet
B14: 1Q | C14: 1 | D14: 2 | E14: 윤현기
B16: 2Q | C16: 0 | D16: 1
B18: 3Q | C18: 2 | D18: 0 | E18: 윤현기 | F18: 박주연 | I18: 김인혁 | J18: 이병현 | M18: 송윤상 | N18: 윤현기 | Q18: 차승원 | R18: 김성준 | S18: 박주연 | T18: 정민수 | V18: 노민준
B20: 4Q | C20: 2 | D20: 0 | E20: 김종혁 | F20: 김기태 | J20: 김종혁 | M20: 김성준 | N20: 송윤상 | Q20: 차승원 | R20: 정민수 | S20: 박주연 | V20: 노민준
B22: Total | C22: =SUM(C14:C21) -> 5 | D22: =SUM(D14:D21) -> 3
B24: 46100 | C24: 김청축 | D24: 김청축 | E24: Goal | I24: Assist | M24: Balance | Q24: Clean Sheet
B25: 1Q | C25: 2 | D25: 1 | E25: 김진호 | F25: 강기혁 | I25: 유정훈 | J25: 유정훈
E26: 황철우 | I26: 전하늘
B27: 2Q | C27: 4 | D27: 0 | E27: 김진호 | F27: 강기혁 | G27: 강기혁 | H27: 강기혁 | I27: 김용현 | J27: 김용현 | K27: 김용현 | L27: 김진호 | M27: 김용현 | N27: 유정훈 | O27: 김성준 | Q27: 최령창 | R27: 유상근 | S27: 이새샘 | T27: 박주연 | V27: 최경영
B29: 3Q | C29: 2 | D29: 0 | E29: 임태환 | F29: 김기태 | M29: 강관석 | N29: 양진웅 | Q29: 이성관 | R29: 한의현 | S29: 노민준 | T29: 이찬영 | V29: 최경영
B31: 4Q | C31: 4 | D31: 0 | E31: 김진호 | F31: 김성준 | G31: 강기혁 | H31: 최경영 | I31: 김용현 | J31: 최경영 | K31: 김용현 | L31: 강기혁 | M31: 김용현 | N31: 유정훈 | O31: 김성준 | Q31: 최령창 | R31: 유상근 | S31: 양진웅 | T31: 박주연 | V31: 이새샘
B33: 5Q | C33: 2 | D33: 2 | E33: 김용현 | F33: 최경영 | I33: 유상근
E34: 조진한 | F34: 김기태 | I34: 김기태 | J34: 김민섭
B35: Total | C35: =SUM(C25:C34) -> 14 | D35: =SUM(D25:D34) -> 3
B37: 46107 | C37: 김청축 | D37: 미농FC | E37: Goal | I37: Assist | M37: Balance | Q37: Clean Sheet
B38: 1Q | C38: 0 | D38: 2
B40: 2Q | C40: 1 | D40: 4 | E40: 김인혁
B42: 3Q | C42: 0 | D42: 2
B44: 4Q | C44: 2 | D44: 2 | E44: 김성준 | F44: 김성준 | I44: 유정훈 | J44: 김기태
B46: Total | C46: =SUM(C38:C45) -> 3 | D46: =SUM(D38:D45) -> 10
B49: 46114 | C49: 김청축 | D49: 김청축 | E49: Goal | I49: Assist | M49: Balance | Q49: Clean Sheet
B50: 1Q | C50: 0 | D50: 1 | E50: 오우영 | I50: 전나현 | M50: 조진한 | N50: 전나현 | O50: 오우영 | Q50: 한중희 | R50: 이승윤 | S50: 조현우 | T50: 최령창 | V50: 김우인
B52: 2Q | C52: 0 | D52: 0 | Q52: 유상근 | R52: 김성준 | S52: 정민수 | T52: 최병준 | V52: 최경영
Q53: 최령창 | R53: 이새샘 | S53: 손경호 | T53: 이찬영 | V53: 김우인
B54: 3Q | C54: 3 | D54: 0 | E54: 전성환 | F54: 김진호 | G54: 오상준 | I54: 임태환 | M54: 강관석 | N54: 오상준 | O54: 김성수 | Q54: 정민수 | R54: 노민준 | S54: 이새샘 | T54: 최경영 | V54: 김성준
B56: 4Q | C56: 1 | D56: 1 | E56: 홍석준 | I56: 전나현
E57: 김기태
B58: 5Q | C58: 2 | D58: 0 | E58: 강기혁 | F58: 오상준 | I58: 김진호 | J58: 최령창 | M58: 김용현 | N58: 김성준 | Q58: 최령창 | R58: 최경영 | S58: 유상근 | T58: 최병준
B60: Total | C60: =SUM(C50:C59) -> 6 | D60: =SUM(D50:D59) -> 2
B63: 46128 | C63: Black | D63: Red | E63: Goal | I63: Assist | M63: Balance | Q63: Clean Sheet
B64: 1Q | C64: 0 | D64: 1
E65: 김태성 | I65: 김진호 | M65: 김송환 | N65: 김성수 | O65: 오성찬 | Q65: 황석원 | R65: 정민수 | S65: 김성준 | T65: 이호행 | V65: 서영진
B66: 2Q | C66: 0 | D66: 0 | Q66: 최령창 | R66: 문준수 | S66: 김성준 | T66: 서영진 | V66: 황석원
...

Sheet 개인기록Sheet
D2: =SUM(D4:D95) -> 159 | E2: =SUM(E4:E95) -> 114 | F2: =SUM(F4:F95) -> 111 | G2: =SUM(G4:G95) -> 186 | H2: =SUM(H4:H95) -> 48
A3: 인원 | B3: 이름 | C3: 개인 Point | D3: Goal (0.2) | E3: Assist (0.2) | F3: Balance (0.3) | G3: C/S DF (0.2) | H3: C/S GK (0.2) | I3: Total | K3: 순위 | L3: Goal | N3: Assist | P3: Balance | R3: C/S DF | T3: C/S GK
A4: =종합Sheet!A4 -> 1 | B4: =종합Sheet!B4 -> 김인혁 | C4: =((D4+E4+G4+H4)*0.2)+(F4*0.3) -> 2.6 | D4: =COUNTIF(경기기록Sheet!$E:$H,B4) -> 4 | E4: =COUNTIF(경기기록Sheet!$I:$L,B4) -> 7 | F4: =COUNTIF(경기기록Sheet!$M:$P,B4) -> 0 | G4: =COUNTIF(경기기록Sheet!$Q:$U,B4) -> 1 | H4: =COUNTIF(경기기록Sheet!$V:$V,B4) -> 1 | I4: =SUM(D4:H4) -> 13 | K4: 1 | L4: 김진호 | M4: =VLOOKUP(L4,$B$4:$H$133,3,FALSE) -> 24 | N4: 김진호 | O4: =VLOOKUP(N4,$B$4:$H$133,4,FALSE) -> 12 | P4: 김성준 | Q4: =VLOOKUP(P4,$B$4:$H$133,5,FALSE) -> 17 | R4: 유상근 | S4: =VLOOKUP(R4,$B$4:$H$133,6,FALSE) -> 23 | T4: 최경영 | U4: =VLOOKUP(T4,$B$4:$H$133,7,FALSE) -> 16
A5: =종합Sheet!A5 -> 2 | B5: =종합Sheet!B5 -> 신재경 | C5: =((D5+E5+G5+H5)*0.2)+(F5*0.3) -> 0.9 | D5: =COUNTIF(경기기록Sheet!$E:$H,B5) -> 1 | E5: =COUNTIF(경기기록Sheet!$I:$L,B5) -> 1 | F5: =COUNTIF(경기기록Sheet!$M:$P,B5) -> 1 | G5: =COUNTIF(경기기록Sheet!$Q:$U,B5) -> 0 | H5: =COUNTIF(경기기록Sheet!$V:$V,B5) -> 1 | I5: =SUM(D5:H5) -> 4 | K5: 2 | L5: 강기혁 | M5: =VLOOKUP(L5,$B$4:$H$133,3,FALSE) -> 17 | N5: 김용현 | O5: =VLOOKUP(N5,$B$4:$H$133,4,FALSE) -> 8 | P5: 조진한 | Q5: =VLOOKUP(P5,$B$4:$H$133,5,FALSE) -> 16 | R5: 정민수 | S5: =VLOOKUP(R5,$B$4:$H$133,6,FALSE) -> 23 | T5: 김우인 | U5: =VLOOKUP(T5,$B$4:$H$133,7,FALSE) -> 12
A6: =종합Sheet!A6 -> 3 | B6: =종합Sheet!B6 -> 정효태 | C6: =((D6+E6+G6+H6)*0.2)+(F6*0.3) -> 0 | D6: =COUNTIF(경기기록Sheet!$E:$H,B6) -> 0 | E6: =COUNTIF(경기기록Sheet!$I:$L,B6) -> 0 | F6: =COUNTIF(경기기록Sheet!$M:$P,B6) -> 0 | G6: =COUNTIF(경기기록Sheet!$Q:$U,B6) -> 0 | H6: =COUNTIF(경기기록Sheet!$V:$V,B6) -> 0 | I6: =SUM(D6:H6) -> 0 | K6: 3 | L6: 정재명 | M6: =VLOOKUP(L6,$B$4:$H$133,3,FALSE) -> 17 | N6: 김인혁 | O6: =VLOOKUP(N6,$B$4:$H$133,4,FALSE) -> 7 | P6: 김송환 | Q6: =VLOOKUP(P6,$B$4:$H$133,5,FALSE) -> 9 | R6: 노민준 | S6: =VLOOKUP(R6,$B$4:$H$133,6,FALSE) -> 18 | T6: 손경호 | U6: =VLOOKUP(T6,$B$4:$H$133,7,FALSE) -> 5
A7: =종합Sheet!A7 -> 4 | B7: =종합Sheet!B7 -> 이승민 | C7: =((D7+E7+G7+H7)*0.2)+(F7*0.3) -> 0 | D7: =COUNTIF(경기기록Sheet!$E:$H,B7) -> 0 | E7: =COUNTIF(경기기록Sheet!$I:$L,B7) -> 0 | F7: =COUNTIF(경기기록Sheet!$M:$P,B7) -> 0 | G7: =COUNTIF(경기기록Sheet!$Q:$U,B7) -> 0 | H7: =COUNTIF(경기기록Sheet!$V:$V,B7) -> 0 | I7: =SUM(D7:H7) -> 0 | K7: 4 | L7: 임태환 | M7: =VLOOKUP(L7,$B$4:$H$133,3,FALSE) -> 15 | N7: 김기태 | O7: =VLOOKUP(N7,$B$4:$H$133,4,FALSE) -> 7 | P7: 강관석 | Q7: =VLOOKUP(P7,$B$4:$H$133,5,FALSE) -> 8 | R7: 문준수 | S7: =VLOOKUP(R7,$B$4:$H$133,6,FALSE) -> 16 | T7: 노민준 | U7: =VLOOKUP(T7,$B$4:$H$133,7,FALSE) -> 4
A8: =종합Sheet!A8 -> 5 | B8: =종합Sheet!B8 -> 이정석 | C8: =((D8+E8+G8+H8)*0.2)+(F8*0.3) -> 0 | D8: =COUNTIF(경기기록Sheet!$E:$H,B8) -> 0 | E8: =COUNTIF(경기기록Sheet!$I:$L,B8) -> 0 | F8: =COUNTIF(경기기록Sheet!$M:$P,B8) -> 0 | G8: =COUNTIF(경기기록Sheet!$Q:$U,B8) -> 0 | H8: =COUNTIF(경기기록Sheet!$V:$V,B8) -> 0 | I8: =SUM(D8:H8) -> 0 | K8: 5 | L8: 김성준 | M8: =VLOOKUP(L8,$B$4:$H$133,3,FALSE) -> 12 | N8: 김성준 | O8: =VLOOKUP(N8,$B$4:$H$133,4,FALSE) -> 6 | P8: 김용현 | Q8: =VLOOKUP(P8,$B$4:$H$133,5,FALSE) -> 8 | R8: 조현우 | S8: =VLOOKUP(R8,$B$4:$H$133,6,FALSE) -> 16 | T8: 김종혁 | U8: =VLOOKUP(T8,$B$4:$H$133,7,FALSE) -> 3
A9: =종합Sheet!A9 -> 6 | B9: =종합Sheet!B9 -> 강종찬 | C9: =((D9+E9+G9+H9)*0.2)+(F9*0.3) -> 1 | D9: =COUNTIF(경기기록Sheet!$E:$H,B9) -> 0 | E9: =COUNTIF(경기기록Sheet!$I:$L,B9) -> 0 | F9: =COUNTIF(경기기록Sheet!$M:$P,B9) -> 0 | G9: =COUNTIF(경기기록Sheet!$Q:$U,B9) -> 4 | H9: =COUNTIF(경기기록Sheet!$V:$V,B9) -> 1 | I9: =SUM(D9:H9) -> 5 | K9: 6 | L9: 김종혁 | M9: =VLOOKUP(L9,$B$4:$H$133,3,FALSE) -> 12 | N9: 강기혁 | O9: =VLOOKUP(N9,$B$4:$H$133,4,FALSE) -> 5 | P9: 이상현 | Q9: =VLOOKUP(P9,$B$4:$H$133,5,FALSE) -> 8 | R9: 최령창 | S9: =VLOOKUP(R9,$B$4:$H$133,6,FALSE) -> 16 | T9: 이민재 | U9: =VLOOKUP(T9,$B$4:$H$133,7,FALSE) -> 3
A10: =종합Sheet!A10 -> 7 | B10: =종합Sheet!B10 -> 강관석 | C10: =((D10+E10+G10+H10)*0.2)+(F10*0.3) -> 3.6 | D10: =COUNTIF(경기기록Sheet!$E:$H,B10) -> 3 | E10: =COUNTIF(경기기록Sheet!$I:$L,B10) -> 1 | F10: =COUNTIF(경기기록Sheet!$M:$P,B10) -> 8 | G10: =COUNTIF(경기기록Sheet!$Q:$U,B10) -> 0 | H10: =COUNTIF(경기기록Sheet!$V:$V,B10) -> 2 | I10: =SUM(D10:H10) -> 14 | K10: 7 | L10: 김우인 | M10: =VLOOKUP(L10,$B$4:$H$133,3,FALSE) -> 11 | N10: 오우영 | O10: =VLOOKUP(N10,$B$4:$H$133,4,FALSE) -> 5 | P10: 김성수 | Q10: =VLOOKUP(P10,$B$4:$H$133,5,FALSE) -> 7 | R10: 한상규 | S10: =VLOOKUP(R10,$B$4:$H$133,6,FALSE) -> 15 | T10: 강관석 | U10: =VLOOKUP(T10,$B$4:$H$133,7,FALSE) -> 2
A11: =종합Sheet!A11 -> 8 | B11: =종합Sheet!B11 -> 강기혁 | C11: =((D11+E11+G11+H11)*0.2)+(F11*0.3) -> 5.6 | D11: =COUNTIF(경기기록Sheet!$E:$H,B11) -> 17 | E11: =COUNTIF(경기기록Sheet!$I:$L,B11) -> 5 | F11: =COUNTIF(경기기록Sheet!$M:$P,B11) -> 4 | G11: =COUNTIF(경기기록Sheet!$Q:$U,B11) -> 0 | H11: =COUNTIF(경기기록Sheet!$V:$V,B11) -> 0 | I11: =SUM(D11:H11) -> 26 | K11: 8 | L11: 김기태 | M11: =VLOOKUP(L11,$B$4:$H$133,3,FALSE) -> 10 | N11: 이상현 | O11: =VLOOKUP(N11,$B$4:$H$133,4,FALSE) -> 5 | P11: 오상준 | Q11: =VLOOKUP(P11,$B$4:$H$133,5,FALSE) -> 7 | R11: 이승윤 | S11: =VLOOKUP(R11,$B$4:$H$133,6,FALSE) -> 13 | T11: 김기문 | U11: =VLOOKUP(T11,$B$4:$H$133,7,FALSE) -> 2
A12: =종합Sheet!A12 -> 9 | B12: =종합Sheet!B12 -> 강도일 | C12: =((D12+E12+G12+H12)*0.2)+(F12*0.3) -> 0 | D12: =COUNTIF(경기기록Sheet!$E:$H,B12) -> 0 | E12: =COUNTIF(경기기록Sheet!$I:$L,B12) -> 0 | F12: =COUNTIF(경기기록Sheet!$M:$P,B12) -> 0 | G12: =COUNTIF(경기기록Sheet!$Q:$U,B12) -> 0 | H12: =COUNTIF(경기기록Sheet!$V:$V,B12) -> 0 | I12: =SUM(D12:H12) -> 0 | K12: 9 | L12: 류서진 | M12: =VLOOKUP(L12,$B$4:$H$133,3,FALSE) -> 9 | N12: 정재명 | O12: =VLOOKUP(N12,$B$4:$H$133,4,FALSE) -> 5 | P12: 김기문 | Q12: =VLOOKUP(P12,$B$4:$H$133,5,FALSE) -> 6 | R12: 황석원 | S12: =VLOOKUP(R12,$B$4:$H$133,6,FALSE) -> 13 | T12: 이새샘 | U12: =VLOOKUP(T12,$B$4:$H$133,7,FALSE) -> 2
A13: =종합Sheet!A13 -> 10 | B13: =종합Sheet!B13 -> 강일수 | C13: =((D13+E13+G13+H13)*0.2)+(F13*0.3) -> 0 | D13: =COUNTIF(경기기록Sheet!$E:$H,B13) -> 0 | E13: =COUNTIF(경기기록Sheet!$I:$L,B13) -> 0 | F13: =COUNTIF(경기기록Sheet!$M:$P,B13) -> 0 | G13: =COUNTIF(경기기록Sheet!$Q:$U,B13) -> 0 | H13: =COUNTIF(경기기록Sheet!$V:$V,B13) -> 0 | I13: =SUM(D13:H13) -> 0 | K13: 10 | L13: 조진한 | M13: =VLOOKUP(L13,$B$4:$H$133,3,FALSE) -> 8 | N13: 김종혁 | O13: =VLOOKUP(N13,$B$4:$H$133,4,FALSE) -> 4 | P13: 오우영 | Q13: =VLOOKUP(P13,$B$4:$H$133,5,FALSE) -> 5 | R13: 이새샘 | S13: =VLOOKUP(R13,$B$4:$H$133,6,FALSE) -> 11 | T13: 최령창 | U13: =VLOOKUP(T13,$B$4:$H$133,7,FALSE) -> 2
A14: =종합Sheet!A14 -> 11 | B14: =종합Sheet!B14 -> 구교훈 | C14: =((D14+E14+G14+H14)*0.2)+(F14*0.3) -> 0 | D14: =COUNTIF(경기기록Sheet!$E:$H,B14) -> 0 | E14: =COUNTIF(경기기록Sheet!$I:$L,B14) -> 0 | F14: =COUNTIF(경기기록Sheet!$M:$P,B14) -> 0 | G14: =COUNTIF(경기기록Sheet!$Q:$U,B14) -> 0 | H14: =COUNTIF(경기기록Sheet!$V:$V,B14) -> 0 | I14: =SUM(D14:H14) -> 0 | K14: 11 | L14: 허동혁 | M14: =VLOOKUP(L14,$B$4:$H$133,3,FALSE) -> 6 | N14: 오상준 | O14: =VLOOKUP(N14,$B$4:$H$133,4,FALSE) -> 4 | P14: 전나현 | Q14: =VLOOKUP(P14,$B$4:$H$133,5,FALSE) -> 5 | R14: 이성관 | S14: =VLOOKUP(R14,$B$4:$H$133,6,FALSE) -> 10 | T14: 한의현 | U14: =VLOOKUP(T14,$B$4:$H$133,7,FALSE) -> 2
A15: =종합Sheet!A15 -> 12 | B15: =종합Sheet!B15 -> 권민강 | C15: =((D15+E15+G15+H15)*0.2)+(F15*0.3) -> 0.6 | D15: =COUNTIF(경기기록Sheet!$E:$H,B15) -> 1 | E15: =COUNTIF(경기기록Sheet!$I:$L,B15) -> 2 | F15: =COUNTIF(경기기록Sheet!$M:$P,B15) -> 0 | G15: =COUNTIF(경기기록Sheet!$Q:$U,B15) -> 0 | H15: =COUNTIF(경기기록Sheet!$V:$V,B15) -> 0 | I15: =SUM(D15:H15) -> 3 | K15: 12 | L15: 손경호 | M15: =VLOOKUP(L15,$B$4:$H$133,3,FALSE) -> 5 | N15: 전나현 | O15: =VLOOKUP(N15,$B$4:$H$133,4,FALSE) -> 4 | P15: 황건호 | Q15: =VLOOKUP(P15,$B$4:$H$133,5,FALSE) -> 5 | R15: 김성준 | S15: =VLOOKUP(R15,$B$4:$H$133,6,FALSE) -> 9
A16: =종합Sheet!A16 -> 13 | B16: =종합Sheet!B16 -> 김기문 | C16: =((D16+E16+G16+H16)*0.2)+(F16*0.3) -> 3.8 | D16: =COUNTIF(경기기록Sheet!$E:$H,B16) -> 3 | E16: =COUNTIF(경기기록Sheet!$I:$L,B16) -> 3 | F16: =COUNTIF(경기기록Sheet!$M:$P,B16) -> 6 | G16: =COUNTIF(경기기록Sheet!$Q:$U,B16) -> 2 | H16: =COUNTIF(경기기록Sheet!$V:$V,B16) -> 2 | I16: =SUM(D16:H16) -> 16 | K16: 13 | L16: 김인혁 | M16: =VLOOKUP(L16,$B$4:$H$133,3,FALSE) -> 4 | N16: 정민수 | O16: =VLOOKUP(N16,$B$4:$H$133,4,FALSE) -> 4 | R16: 박주연 | S16: =VLOOKUP(R16,$B$4:$H$133,6,FALSE) -> 9
A17: =종합Sheet!A17 -> 14 | B17: =종합Sheet!B17 -> 김기태 | C17: =((D17+E17+G17+H17)*0.2)+(F17*0.3) -> 3.8 | D17: =COUNTIF(경기기록Sheet!$E:$H,B17) -> 10 | E17: =COUNTIF(경기기록Sheet!$I:$L,B17) -> 7 | F17: =COUNTIF(경기기록Sheet!$M:$P,B17) -> 0 | G17: =COUNTIF(경기기록Sheet!$Q:$U,B17) -> 1 | H17: =COUNTIF(경기기록Sheet!$V:$V,B17) -> 1 | I17: =SUM(D17:H17) -> 19 | K17: 14 | L17: 신기웅 | M17: =VLOOKUP(L17,$B$4:$H$133,3,FALSE) -> 4 | R17: 한중희 | S17: =VLOOKUP(R17,$B$4:$H$133,6,FALSE) -> 8
A18: =종합Sheet!A18 -> 15 | B18: =종합Sheet!B18 -> 김덕준 | C18: =((D18+E18+G18+H18)*0.2)+(F18*0.3) -> 0 | D18: =COUNTIF(경기기록Sheet!$E:$H,B18) -> 0 | E18: =COUNTIF(경기기록Sheet!$I:$L,B18) -> 0 | F18: =COUNTIF(경기기록Sheet!$M:$P,B18) -> 0 | G18: =COUNTIF(경기기록Sheet!$Q:$U,B18) -> 0 | H18: =COUNTIF(경기기록Sheet!$V:$V,B18) -> 0 | I18: =SUM(D18:H18) -> 0 | K18: 15 | L18: 황건호 | M18: =VLOOKUP(L18,$B$4:$H$133,3,FALSE) -> 4
A19: =종합Sheet!A19 -> 16 | B19: =종합Sheet!B19 -> 김도원 | C19: =((D19+E19+G19+H19)*0.2)+(F19*0.3) -> 0 | D19: =COUNTIF(경기기록Sheet!$E:$H,B19) -> 0 | E19: =COUNTIF(경기기록Sheet!$I:$L,B19) -> 0 | F19: =COUNTIF(경기기록Sheet!$M:$P,B19) -> 0 | G19: =COUNTIF(경기기록Sheet!$Q:$U,B19) -> 0 | H19: =COUNTIF(경기기록Sheet!$V:$V,B19) -> 0 | I19: =SUM(D19:H19) -> 0
A20: =종합Sheet!A20 -> 17 | B20: =종합Sheet!B20 -> 김민섭 | C20: =((D20+E20+G20+H20)*0.2)+(F20*0.3) -> 0.4 | D20: =COUNTIF(경기기록Sheet!$E:$H,B20) -> 0 | E20: =COUNTIF(경기기록Sheet!$I:$L,B20) -> 1 | F20: =COUNTIF(경기기록Sheet!$M:$P,B20) -> 0 | G20: =COUNTIF(경기기록Sheet!$Q:$U,B20) -> 1 | H20: =COUNTIF(경기기록Sheet!$V:$V,B20) -> 0 | I20: =SUM(D20:H20) -> 2
A21: =종합Sheet!A21 -> 18 | B21: =종합Sheet!B21 -> 김민찬 | C21: =((D21+E21+G21+H21)*0.2)+(F21*0.3) -> 0 | D21: =COUNTIF(경기기록Sheet!$E:$H,B21) -> 0 | E21: =COUNTIF(경기기록Sheet!$I:$L,B21) -> 0 | F21: =COUNTIF(경기기록Sheet!$M:$P,B21) -> 0 | G21: =COUNTIF(경기기록Sheet!$Q:$U,B21) -> 0 | H21: =COUNTIF(경기기록Sheet!$V:$V,B21) -> 0 | I21: =SUM(D21:H21) -> 0
A22: =종합Sheet!A22 -> 19 | B22: =종합Sheet!B22 -> 김범기 | C22: =((D22+E22+G22+H22)*0.2)+(F22*0.3) -> 0 | D22: =COUNTIF(경기기록Sheet!$E:$H,B22) -> 0 | E22: =COUNTIF(경기기록Sheet!$I:$L,B22) -> 0 | F22: =COUNTIF(경기기록Sheet!$M:$P,B22) -> 0 | G22: =COUNTIF(경기기록Sheet!$Q:$U,B22) -> 0 | H22: =COUNTIF(경기기록Sheet!$V:$V,B22) -> 0 | I22: =SUM(D22:H22) -> 0
A23: =종합Sheet!A23 -> 20 | B23: =종합Sheet!B23 -> 김병준 | C23: =((D23+E23+G23+H23)*0.2)+(F23*0.3) -> 0 | D23: =COUNTIF(경기기록Sheet!$E:$H,B23) -> 0 | E23: =COUNTIF(경기기록Sheet!$I:$L,B23) -> 0 | F23: =COUNTIF(경기기록Sheet!$M:$P,B23) -> 0 | G23: =COUNTIF(경기기록Sheet!$Q:$U,B23) -> 0 | H23: =COUNTIF(경기기록Sheet!$V:$V,B23) -> 0 | I23: =SUM(D23:H23) -> 0
A24: =종합Sheet!A24 -> 21 | B24: =종합Sheet!B24 -> 김부건 | C24: =((D24+E24+G24+H24)*0.2)+(F24*0.3) -> 1.3 | D24: =COUNTIF(경기기록Sheet!$E:$H,B24) -> 2 | E24: =COUNTIF(경기기록Sheet!$I:$L,B24) -> 2 | F24: =COUNTIF(경기기록Sheet!$M:$P,B24) -> 1 | G24: =COUNTIF(경기기록Sheet!$Q:$U,B24) -> 0 | H24: =COUNTIF(경기기록Sheet!$V:$V,B24) -> 1 | I24: =SUM(D24:H24) -> 6
A25: =종합Sheet!A25 -> 22 | B25: =종합Sheet!B25 -> 김성수 | C25: =((D25+E25+G25+H25)*0.2)+(F25*0.3) -> 2.9 | D25: =COUNTIF(경기기록Sheet!$E:$H,B25) -> 2 | E25: =COUNTIF(경기기록Sheet!$I:$L,B25) -> 2 | F25: =COUNTIF(경기기록Sheet!$M:$P,B25) -> 7 | G25: =COUNTIF(경기기록Sheet!$Q:$U,B25) -> 0 | H25: =COUNTIF(경기기록Sheet!$V:$V,B25) -> 0 | I25: =SUM(D25:H25) -> 11
A26: =종합Sheet!A26 -> 23 | B26: =종합Sheet!B26 -> 김성준 | C26: =((D26+E26+G26+H26)*0.2)+(F26*0.3) -> 10.7 | D26: =COUNTIF(경기기록Sheet!$E:$H,B26) -> 12 | E26: =COUNTIF(경기기록Sheet!$I:$L,B26) -> 6 | F26: =COUNTIF(경기기록Sheet!$M:$P,B26) -> 17 | G26: =COUNTIF(경기기록Sheet!$Q:$U,B26) -> 9 | H26: =COUNTIF(경기기록Sheet!$V:$V,B26) -> 1 | I26: =SUM(D26:H26) -> 45
A27: =종합Sheet!A27 -> 24 | B27: =종합Sheet!B27 -> 김송환 | C27: =((D27+E27+G27+H27)*0.2)+(F27*0.3) -> 3.1 | D27: =COUNTIF(경기기록Sheet!$E:$H,B27) -> 0 | E27: =COUNTIF(경기기록Sheet!$I:$L,B27) -> 1 | F27: =COUNTIF(경기기록Sheet!$M:$P,B27) -> 9 | G27: =COUNTIF(경기기록Sheet!$Q:$U,B27) -> 0 | H27: =COUNTIF(경기기록Sheet!$V:$V,B27) -> 1 | I27: =SUM(D27:H27) -> 11
A28: =종합Sheet!A28 -> 25 | B28: =종합Sheet!B28 -> 김영태 | C28: =((D28+E28+G28+H28)*0.2)+(F28*0.3) -> 0 | D28: =COUNTIF(경기기록Sheet!$E:$H,B28) -> 0 | E28: =COUNTIF(경기기록Sheet!$I:$L,B28) -> 0 | F28: =COUNTIF(경기기록Sheet!$M:$P,B28) -> 0 | G28: =COUNTIF(경기기록Sheet!$Q:$U,B28) -> 0 | H28: =COUNTIF(경기기록Sheet!$V:$V,B28) -> 0 | I28: =SUM(D28:H28) -> 0
A29: =종합Sheet!A29 -> 26 | B29: =종합Sheet!B29 -> 김용빈 | C29: =((D29+E29+G29+H29)*0.2)+(F29*0.3) -> 0 | D29: =COUNTIF(경기기록Sheet!$E:$H,B29) -> 0 | E29: =COUNTIF(경기기록Sheet!$I:$L,B29) -> 0 | F29: =COUNTIF(경기기록Sheet!$M:$P,B29) -> 0 | G29: =COUNTIF(경기기록Sheet!$Q:$U,B29) -> 0 | H29: =COUNTIF(경기기록Sheet!$V:$V,B29) -> 0 | I29: =SUM(D29:H29) -> 0
A30: =종합Sheet!A30 -> 27 | B30: =종합Sheet!B30 -> 김용현 | C30: =((D30+E30+G30+H30)*0.2)+(F30*0.3) -> 4.6 | D30: =COUNTIF(경기기록Sheet!$E:$H,B30) -> 2 | E30: =COUNTIF(경기기록Sheet!$I:$L,B30) -> 8 | F30: =COUNTIF(경기기록Sheet!$M:$P,B30) -> 8 | G30: =COUNTIF(경기기록Sheet!$Q:$U,B30) -> 1 | H30: =COUNTIF(경기기록Sheet!$V:$V,B30) -> 0 | I30: =SUM(D30:H30) -> 19
... A122: =종합Sheet!A122 -> 119 | B122: =종합Sheet!B122 -> 박지수 | C122: =((D122+E122+G122+H122)*0.2)+(F122*0.3) -> 1.6 | D122: =COUNTIF(경기기록Sheet!$E:$H,B122) -> 1 | E122: =COUNTIF(경기기록Sheet!$I:$L,B122) -> 1 | F122: =COUNTIF(경기기록Sheet!$M:$P,B122) -> 0 | G122: =COUNTIF(경기기록Sheet!$Q:$U,B122) -> 6 | H122: =COUNTIF(경기기록Sheet!$V:$V,B122) -> 0 | I122: =SUM(D122:H122) -> 8

Sheet 시상대상(23)
B3: 항목 | C3: 설명 | D3: 비고 | E3: 1순위 | G3: 2순위 | I3: 3순위 | K3: 4순위 | M3: 5순위 | P3: 인원 | Q3: 최종 수상자 | R3: 비고
A4: 1 | B4: MVP | C4: 최다 출석 | D4: 기존 MVP 제외, 중복 수상 가능 | E4: 김인혁 | F4: 42 | G4: 황석원 | H4: 36 | I4: 문준수 | J4: 27 | K4: 강기혁 | L4: 27 | M4: 김부건 | N4: 26 | P4: 1 | Q4: 강기혁 | R4: Score
A5: 2 | B5: 득점왕 | C5: 최다 득점 | D5: 1명 | E5: 강기혁 | F5: 20 | G5: 김부건 | H5: 17 | I5: 전성환 | J5: 13 | K5: 김성수 | L5: 12 | M5: 손경호 | N5: 10 | P5: 2 | Q5: 김대현 | R5: Assist
A6: 3 | B6: 도움왕 | C6: 최다 도움 | D6: 1명 | E6: 김대현 | F6: 14 | G6: 정효태 | H6: 11 | I6: 강기혁 | J6: 11 | K6: 김부건 | L6: 8 | M6: 김성수 | N6: 8 | P6: 3 | Q6: 김송환 | R6: Best MF
A7: 4 | B7: 밸런스왕 | C7: 최다 밸런스 | D7: 1명 | E7: 김송환 | F7: 24 | G7: 김부건 | H7: 21 | I7: 신재경 | J7: 19 | K7: 김성수 | L7: 19 | M7: 김용현 | N7: 17 | P7: 4 | Q7: 황석원 | R7: Best DF
A8: 5 | B8: 수비왕1 | C8: 최다 클린시트 | D8: 2명 | E8: 황석원 | F8: 50 | G8: 문준수 | H8: 40 | I8: 이성관 | J8: 34 | K8: 강종찬 | L8: 25 | M8: 김덕준 | N8: 24 | P8: 5 | Q8: 문준수 | R8: Best DF
A9: 6 | B9: 키퍼왕 | C9: 최다 클린시트 | D9: 1명 | E9: 최경영 | F9: 34 | G9: 김영태 | H9: 15 | I9: 이재민 | J9: 8 | P9: 6 | Q9: 최경영 | R9: Best GK
A10: 7 | B10: 베스트11 | C10: 수상자 제외 최다 종합 포인트 | D10: 5명 | E10: 황석원 | F10: 47.7 | G10: 김인혁 | H10: 45.2 | I10: 김부건 | J10: 38.3 | K10: 문준수 | L10: 36.4 | M10: 정효태 | N10: 34.2 | P10: 7 | Q10: 김부건
E11: 강기혁 | F11: 34.2 | G11: 김성수 | H11: 33.5 | I11: 신재경 | J11: 33.3 | K11: 최경영 | L11: 32.6 | M11: 이성관 | N11: 31.6 | P11: 8 | Q11: 정효태
A12: 8 | B12: 신인왕1 | C12: 전년/금년 합산 최다 출석 | D12: 역대 수상자 제외 | E12: 강기혁 | F12: 27 | G12: 문준수 | H12: 27 | I12: 홍석준 | J12: 24 | K12: 박주연 | L12: 23 | M12: 손경호 | N12: 23 | P12: 9 | Q12: 김성수
A13: 9 | B13: 신인왕2 | C13: 전년도 등록 최다 출석 | D13: 역대 수상자 제외 | E13: 강기혁 | F13: 27 | G13: 문준수 | H13: 27 | I13: 홍석준 | J13: 24 | K13: 김동인 | L13: 22 | M13: 김형원 | N13: 21 | P13: 10 | Q13: 신재경
A14: 10 | B14: 신인왕3 | C14: 금년 등록 최다 출석 | D14: 역대 수상자 제외 | E14: 박주연 | F14: 23 | G14: 손경호 | H14: 23 | I14: 김성수 | J14: 22 | K14: 유인상 | L14: 20 | M14: 김덕준 | N14: 19 | P14: 11 | Q14: 이성관
A15: 11 | B15: 추천 | C15: 운영진 추천 | P15: 12 | Q15: 홍석준 | R15: Young Player
P16: 13 | Q16: 김형원 | R16: Young Player
A17: ※ 24년 DF 2명, GK 1명에서 DF/GK 통합 2명으로 수정 | P17: 14 | Q17: 박주연 | R17: Young Player
A18: ※ 베스트11 종합 포인트 5명에서 종합 포인트 3명, 출석 3명으로 수정 | P18: 15 | Q18: 손경호 | R18: Young Player

Sheet 시상대상(24)
D2: 1순위 | J2: 2순위 | P2: 3순위
A3: 부분 | B3: 대상 | D3: 부분 | F3: 대상 | G3: 비고1 | J3: 부분 | L3: 대상 | M3: 출석 | N3: 수상이력 | P3: 부분 | R3: 대상 | S3: 출석 | T3: 수상이력 | U3: 수상이력 | V3: 수상이력
A4: MVP | B4: 손경호 | D4: Best Eleven | E4: 1 | F4: 김인혁 | J4: Best Attendance | K4: 1 | L4: 김인혁 | M4: 39 | N4: =IF(1=COUNTIF($F$5:$F$15,L4),"수상","미수상") -> 미수상 | P4: Young Player | Q4: 1 | R4: 손경호 | S4: 30 | T4: =IF(1=COUNTIF($F$4:$F$14,R4),"수상","미수상") -> 수상 | U4: =IF(1=COUNTIF($L$4:$L$14,R4),"수상","미수상") -> 수상
A5: MVP (교대) | B5: 유정훈 | E5: 2 | F5: 유정훈 | G5: MVP | H5: Best MF | K5: 2 | L5: 손경호 | M5: 30 | N5: =IF(1=COUNTIF($F$5:$F$15,L5),"수상","미수상") -> 수상 | Q5: 2 | R5: 김우인 | S5: 26 | T5: =IF(1=COUNTIF($F$4:$F$14,R5),"수상","미수상") -> 미수상 | U5: =IF(1=COUNTIF($L$4:$L$14,R5),"수상","미수상") -> 수상
A6: Top Score | B6: 김성수 | E6: 3 | F6: 최경영 | G6: Best DF/GK | K6: 3 | L6: 유정훈 | M6: 30 | N6: =IF(1=COUNTIF($F$5:$F$15,L6),"수상","미수상") -> 수상 | Q6: 3 | R6: 박주연 | S6: 25 | T6: =IF(1=COUNTIF($F$4:$F$14,R6),"수상","미수상") -> 미수상 | U6: =IF(1=COUNTIF($L$4:$L$14,R6),"수상","미수상") -> 수상
A7: Assist | B7: 김성수 | E7: 4 | F7: 문준수 | G7: Best DF/GK | K7: 4 | L7: 최경영 | M7: 29 | N7: =IF(1=COUNTIF($F$5:$F$15,L7),"수상","미수상") -> 수상 | Q7: 4 | R7: 임태환 | S7: 25 | T7: =IF(1=COUNTIF($F$4:$F$14,R7),"수상","미수상") -> 미수상 | U7: =IF(1=COUNTIF($L$4:$L$14,R7),"수상","미수상") -> 수상
A8: Best MF | B8: 유정훈 | E8: 5 | F8: 김종준 | K8: 5 | L8: 김종준 | M8: 28 | N8: =IF(1=COUNTIF($F$5:$F$15,L8),"수상","미수상") -> 수상 | Q8: 5 | R8: 김성준 | S8: 22 | T8: =IF(1=COUNTIF($F$4:$F$14,R8),"수상","미수상") -> 수상 | U8: =IF(1=COUNTIF($L$4:$L$14,R8),"수상","미수상") -> 미수상
A9: Best DF/GK | B9: 문준수 | E9: 6 | F9: 김용현 | K9: 6 | L9: 강기혁 | M9: 27 | N9: =IF(1=COUNTIF($F$5:$F$15,L9),"수상","미수상") -> 수상 | Q9: 6 | R9: 김성수 | S9: 19 | T9: =IF(1=COUNTIF($F$4:$F$14,R9),"수상","미수상") -> 수상 | U9: =IF(1=COUNTIF($L$4:$L$14,R9),"수상","미수상") -> 미수상
A10: Best DF/GK | B10: 최경영 | E10: 7 | F10: 손경호 | G10: MVP | K10: 7 | L10: 문준수 | M10: 27 | N10: =IF(1=COUNTIF($F$5:$F$15,L10),"수상","미수상") -> 수상 | Q10: 7 | R10: 조진한 | S10: 19 | T10: =IF(1=COUNTIF($F$4:$F$14,R10),"수상","미수상") -> 미수상 | U10: =IF(1=COUNTIF($L$4:$L$14,R10),"수상","미수상") -> 미수상
E11: 8 | F11: 강기혁 | K11: 8 | L11: 김용현 | M11: 26 | N11: =IF(1=COUNTIF($F$5:$F$15,L11),"수상","미수상") -> 수상 | Q11: 8 | R11: 한의현 | S11: 19 | T11: =IF(1=COUNTIF($F$4:$F$14,R11),"수상","미수상") -> 미수상 | U11: =IF(1=COUNTIF($L$4:$L$14,R11),"수상","미수상") -> 미수상
E12: 9 | F12: 김성수 | G12: Top Score | H12: Assist | K12: 9 | L12: 김우인 | M12: 26 | N12: =IF(1=COUNTIF($F$5:$F$15,L12),"수상","미수상") -> 수상 | Q12: 9 | R12: 김덕준 | S12: 17 | T12: =IF(1=COUNTIF($F$4:$F$14,R12),"수상","미수상") -> 미수상 | U12: =IF(1=COUNTIF($L$4:$L$14,R12),"수상","미수상") -> 미수상
E13: 10 | F13: 신재경 | K13: 10 | L13: 박주연 | M13: 25 | N13: =IF(1=COUNTIF($F$5:$F$15,L13),"수상","미수상") -> 미수상 | Q13: 10 | R13: 정민수 | S13: 17 | T13: =IF(1=COUNTIF($F$4:$F$14,R13),"수상","미수상") -> 미수상 | U13: =IF(1=COUNTIF($L$4:$L$14,R13),"수상","미수상") -> 미수상
E14: 11 | F14: 김성준 | K14: 11 | L14: 임태환 | M14: 25 | N14: =IF(1=COUNTIF($F$5:$F$15,L14),"수상","미수상") -> 미수상 | Q14: 11 | R14: 황재순 | S14: 16 | T14: =IF(1=COUNTIF($F$4:$F$14,R14),"수상","미수상") -> 미수상 | U14: =IF(1=COUNTIF($L$4:$L$14,R14),"수상","미수상") -> 미수상
E15: 12 | F15: 김우인 | K15: 12 | L15: 조현우 | M15: 25 | N15: =IF(1=COUNTIF($F$5:$F$15,L15),"수상","미수상") -> 미수상 | Q15: 12 | R15: 김민섭 | S15: 14 | T15: =IF(1=COUNTIF($F$4:$F$14,R15),"수상","미수상") -> 미수상 | U15: =IF(1=COUNTIF($L$4:$L$14,R15),"수상","미수상") -> 미수상
E16: 13 | F16: 이성관 | K16: 13 | L16: 신재경 | M16: 24 | N16: =IF(1=COUNTIF($F$5:$F$15,L16),"수상","미수상") -> 수상 | Q16: 13 | R16: 김태성 | S16: 13 | T16: =IF(1=COUNTIF($F$4:$F$14,R16),"수상","미수상") -> 미수상 | U16: =IF(1=COUNTIF($L$4:$L$14,R16),"수상","미수상") -> 미수상
E17: 14 | F17: 김송환 | K17: 14 | L17: 김송환 | M17: 24 | N17: =IF(1=COUNTIF($F$5:$F$15,L17),"수상","미수상") -> 미수상
E18: 15 | F18: 임태환 | K18: 15 | L18: 이성관 | M18: 24 | N18: =IF(1=COUNTIF($F$5:$F$15,L18),"수상","미수상") -> 미수상
K19: 16 | N19: =IF(1=COUNTIF($F$5:$F$15,L19),"수상","미수상") -> 미수상

Sheet 시상대상(25)
B2: 부분 | D2: 출석 | E2: Point | F2: 포인트 | G2: Point | I2: 부분 | K2: 출석 | L2: Point | N2: 부분 | P2: 출석 | Q2: Point | R2: 포인트 | S2: Point
B3: Best Eleven & MVP | C3: 1 | D3: 강관석 | E3: =VLOOKUP(D3,종합Sheet!$B$3:$I$121,8,0) -> 17 | F3: 강관석 | G3: =VLOOKUP(F3,종합Sheet!$B$3:$I$121,7,0) -> 20.6 | I3: TOP SCORER | J3: 1 | K3: 김기문 | L3: 16 | N3: Young Player | O3: 1 | P3: 강관석 | Q3: =VLOOKUP(P3,종합Sheet!$B$3:$I$121,8,0) -> 17 | R3: 강관석 | S3: =VLOOKUP(R3,종합Sheet!$B$3:$I$121,7,0) -> 20.6
C4: 2 | D4: 김인혁 | E4: =VLOOKUP(D4,종합Sheet!$B$3:$I$121,8,0) -> 26 | F4: 유정훈 | G4: =VLOOKUP(F4,종합Sheet!$B$3:$I$121,7,0) -> 9.5 | J4: 2 | K4: 강기혁 | L4: 15 | O4: 2 | P4: 김성준 | Q4: =VLOOKUP(P4,종합Sheet!$B$3:$I$121,8,0) -> 27 | R4: 김성준 | S4: =VLOOKUP(R4,종합Sheet!$B$3:$I$121,7,0) -> 37.7
C5: 3 | D5: 김성준 | E5: =VLOOKUP(D5,종합Sheet!$B$3:$I$121,8,0) -> 27 | F5: 김성준 | G5: =VLOOKUP(F5,종합Sheet!$B$3:$I$121,7,0) -> 37.7 | J5: 3 | K5: 박주연 | L5: 12 | O5: 3 | P5: 조진한 | Q5: =VLOOKUP(P5,종합Sheet!$B$3:$I$121,8,0) -> 25 | R5: 조진한 | S5: =VLOOKUP(R5,종합Sheet!$B$3:$I$121,7,0) -> 32
C6: 4 | D6: 조진한 | E6: =VLOOKUP(D6,종합Sheet!$B$3:$I$121,8,0) -> 25 | F6: 문준수 | G6: =VLOOKUP(F6,종합Sheet!$B$3:$I$121,7,0) -> 22.6 | J6: 4 | K6: 송명섭 | L6: 12 | O6: 4 | P6: 정민수 | Q6: =VLOOKUP(P6,종합Sheet!$B$3:$I$121,8,0) -> 18 | R6: 정민수 | S6: =VLOOKUP(R6,종합Sheet!$B$3:$I$121,7,0) -> 23.8
C7: 5 | D7: 문준수 | E7: =VLOOKUP(D7,종합Sheet!$B$3:$I$121,8,0) -> 19 | F7: 조진한 | G7: =VLOOKUP(F7,종합Sheet!$B$3:$I$121,7,0) -> 32 | J7: 5 | K7: 김우인 | L7: 11 | O7: 5 | P7: 유상근 | Q7: =VLOOKUP(P7,종합Sheet!$B$3:$I$121,8,0) -> 16 | R7: 유상근 | S7: =VLOOKUP(R7,종합Sheet!$B$3:$I$121,7,0) -> 21
C8: 6 | D8: 유정훈 | E8: =VLOOKUP(D8,종합Sheet!$B$3:$I$121,8,0) -> 8 | F8: 김인혁 | G8: =VLOOKUP(F8,종합Sheet!$B$3:$I$121,7,0) -> 28.6 | O8: 6 | P8: 양진웅 | Q8: =VLOOKUP(P8,종합Sheet!$B$3:$I$121,8,0) -> 10 | R8: 양진웅 | S8: =VLOOKUP(R8,종합Sheet!$B$3:$I$121,7,0) -> 12
C9: 7 | D9: 강종찬 | E9: =VLOOKUP(D9,종합Sheet!$B$3:$I$121,8,0) -> 8 | F9: 이상현 | G9: =VLOOKUP(F9,종합Sheet!$B$3:$I$121,7,0) -> 18 | I9: 부분 | K9: 출석 | L9: Point | O9: 7 | P9: 이승윤 | Q9: =VLOOKUP(P9,종합Sheet!$B$3:$I$121,8,0) -> 13 | R9: 송명섭 | S9: =VLOOKUP(R9,종합Sheet!$B$3:$I$121,7,0) -> 1.2
C10: 8 | D10: 김종준 | E10: =VLOOKUP(D10,종합Sheet!$B$3:$I$121,8,0) -> 11 | F10: 김용현 | G10: =VLOOKUP(F10,종합Sheet!$B$3:$I$121,7,0) -> 19.6 | I10: BEST ASSIST | J10: 1 | K10: 유정훈 | L10: 11 | O10: 8 | P10: 송명섭 | Q10: =VLOOKUP(P10,종합Sheet!$B$3:$I$121,8,0) -> 1 | R10: 이승윤 | S10: =VLOOKUP(R10,종합Sheet!$B$3:$I$121,7,0) -> 16.2
C11: 9 | D11: 이상현 | E11: =VLOOKUP(D11,종합Sheet!$B$3:$I$121,8,0) -> 14 | F11: 강종찬 | G11: =VLOOKUP(F11,종합Sheet!$B$3:$I$121,7,0) -> 9 | J11: 2 | K11: 이상현 | L11: 10 | O11: 9 | P11: 허동혁 | Q11: =VLOOKUP(P11,종합Sheet!$B$3:$I$121,8,0) -> 6 | R11: 허동혁 | S11: =VLOOKUP(R11,종합Sheet!$B$3:$I$121,7,0) -> 8.6
C12: 10 | D12: 강기혁 | E12: =VLOOKUP(D12,종합Sheet!$B$3:$I$121,8,0) -> 16 | F12: 강기혁 | G12: =VLOOKUP(F12,종합Sheet!$B$3:$I$121,7,0) -> 21.6 | J12: 3 | K12: 강기혁 | L12: 8 | O12: 10 | P12: 유휴민 | Q12: =VLOOKUP(P12,종합Sheet!$B$3:$I$121,8,0) -> #N/A | R12: 유휴민 | S12: =VLOOKUP(R12,종합Sheet!$B$3:$I$121,7,0) -> #N/A
C13: 11 | D13: 김용현 | E13: =VLOOKUP(D13,종합Sheet!$B$3:$I$121,8,0) -> 15 | F13: 박주연 | G13: =VLOOKUP(F13,종합Sheet!$B$3:$I$121,7,0) -> 17.4 | J13: 4 | K13: 박주연 | L13: 7
C14: 12 | D14: 김우인 | E14: =VLOOKUP(D14,종합Sheet!$B$3:$I$121,8,0) -> 27 | F14: 김우인 | G14: =VLOOKUP(F14,종합Sheet!$B$3:$I$121,7,0) -> 32.6 | J14: 5 | K14: 오우영 | L14: 6
C15: 13 | D15: 박주연 | E15: =VLOOKUP(D15,종합Sheet!$B$3:$I$121,8,0) -> 15 | F15: 김기문 | G15: =VLOOKUP(F15,종합Sheet!$B$3:$I$121,7,0) -> 13.8
C16: 14 | D16: 정민수 | E16: =VLOOKUP(D16,종합Sheet!$B$3:$I$121,8,0) -> 18 | F16: 정민수 | G16: =VLOOKUP(F16,종합Sheet!$B$3:$I$121,7,0) -> 23.8 | I16: 부분 | K16: 출석 | L16: Point
C17: 15 | F17: 한의현 | G17: =VLOOKUP(F17,종합Sheet!$B$3:$I$121,7,0) -> 15.2 | I17: MF OF THE SEASON | J17: 1 | K17: 김용현 | L17: 19
J18: 2 | K18: 강관석 | L18: 18
B19: 부분 | D19: 출석 | J19: 3 | K19: 김송환 | L19: 17
B20: 단장추천 | C20: 1 | D20: 김종준 | E20: 대회준비 | J20: 4 | K20: 유정훈 | L20: 17
C21: 2 | D21: 장희도 | E21: 운동장예약 | J21: 5 | K21: 양진웅 | L21: 16
C22: 3 | D22: 이승민 | E22: 총무10년
I23: 부분 | K23: 출석 | L23: Point
I24: DF OF THE SEASON | J24: 1 | K24: 문준수 | L24: 38
J25: 2 | K25: 한의현 | L25: 34
J26: 3 | K26: 윤창현 | L26: 30
J27: 4 | K27: 차승원 | L27: 29
J28: 5 | K28: 유상근 | L28: 28
J29: 6 | K29: 황석원 | L29: 28
J30: 7 | K30: 강종찬 | L30: 25

Sheet 종합Sheet (외부)
I1: vs Team | J1: FM | K1: 2R | L1: 3R | M1: 4R | N1: 5R | O1: 6R | P1: 7R | Q1: 8R | R1: 9R | S1: 10R | T1: 11R | U1: 12R | V1: 13R | W1: 14R | X1: 15R | Y1: 16R | Z1: 17R | AA1: 18R | AB1: 19R | AC1: 20R | AD1: 21R | AE1: 22R | AF1: 23R | AG1: 24R | AH1: 25R | AI1: 26R | AJ1: 27R | AK1: 28R | AL1: 29R | AM1: 30R | AN1: 31R | AO1: 32R | AP1: 33R | AQ1: 34R | AR1: 35R | AS1: 36R | AT1: 37R | AU1: 38R | AV1: 39R | AW1: 40R | AX1: 41R | AY1: 42R | AZ1: 43R | BA1: 44R | BB1: 45R | BC1: 46R | BD1: 47R | BE1: 48R | BF1: 49R | BG1: 50R
D2: =COUNTIF(D4:D55,"지급") -> 26 | E2: =COUNTIF(E4:E55,"지급") -> 0 | H2: =SUM(J2:AR2)/COUNTA(J2:BB2) -> 2.1333333 | I2: Check | J2: =COUNTA(J4:J67) -> 15 | K2: =COUNTA(K4:K67) -> 19 | L2: =COUNTA(L4:L67) -> 17 | M2: =COUNTA(M4:M67) -> 15 | N2: =COUNTA(N4:N67) -> 14 | O2: =COUNTA(O4:O67) -> 16 | P2: =COUNTA(P4:P67) -> 0 | Q2: =COUNTA(Q4:Q67) -> 0 | ... BG2: =COUNTA(BG4:BG67) -> 0
A3: 인원 | B3: 이름 | C3: 입단일 | D3: 유니폼 | E3: 바람막이 | F3: 카톡 | G3: Rank | H3: 종합 Point | I3: 출석 Point | J3: 45321 | K3: 45350 | L3: 45397 | M3: 45427 | N3: 45427 | O3: 45467
A4: 1 | B4: 김인혁 | C4: =VLOOKUP(B4,종합Sheet!$B$4:$F$133,2,0) -> Origin | D4: =VLOOKUP(B4,종합Sheet!$B$4:$F$133,3,0) -> 지급 | E4: =VLOOKUP(B4,종합Sheet!$B$4:$F$133,4,0) -> 0 | F4: ○ | G4: =RANK(H4,$H$4:$H$37,0) -> 11 | H4: =I4+개인기록Sheet!C4 -> 5.6 | I4: =(COUNTIF(J4:CD4,"출전")*1) -> 3 | J4: 출전 | K4: 출전 | L4: 출전
A5: 2 | B5: 신재경 | C5: =VLOOKUP(B5,종합Sheet!$B$4:$F$133,2,0) -> 2021 | D5: =VLOOKUP(B5,종합Sheet!$B$4:$F$133,3,0) -> 지급 | E5: =VLOOKUP(B5,종합Sheet!$B$4:$F$133,4,0) -> 0 | F5: ○ | G5: =RANK(H5,$H$4:$H$37,0) -> 9 | H5: =I5+개인기록Sheet!C5 -> 5.9 | I5: =(COUNTIF(J5:CD5,"출전")*1) -> 5 | J5: 출전 | K5: 출전 | L5: 출전 | M5: 출전 | O5: 출전
A6: 3 | B6: 정효태 | C6: =VLOOKUP(B6,종합Sheet!$B$4:$F$133,2,0) -> Origin | D6: =VLOOKUP(B6,종합Sheet!$B$4:$F$133,3,0) -> 발주 | E6: =VLOOKUP(B6,종합Sheet!$B$4:$F$133,4,0) -> 0 | F6: ○ | G6: =RANK(H6,$H$4:$H$37,0) -> 26 | H6: =I6+개인기록Sheet!C6 -> 2 | I6: =(COUNTIF(J6:CD6,"출전")*1) -> 2 | K6: 출전 | N6: 출전
A7: 4 | B7: 강종찬 | C7: =VLOOKUP(B7,종합Sheet!$B$4:$F$133,2,0) -> Origin | D7: =VLOOKUP(B7,종합Sheet!$B$4:$F$133,3,0) -> 지급 | E7: =VLOOKUP(B7,종합Sheet!$B$4:$F$133,4,0) -> 0 | F7: ○ | G7: =RANK(H7,$H$4:$H$37,0) -> 29 | H7: =I7+개인기록Sheet!C9 -> 1 | I7: =(COUNTIF(J7:CD7,"출전")*1) -> 0
A8: 5 | B8: 강기혁 | C8: =VLOOKUP(B8,종합Sheet!$B$4:$F$133,2,0) -> 2022 | D8: =VLOOKUP(B8,종합Sheet!$B$4:$F$133,3,0) -> 지급 | E8: =VLOOKUP(B8,종합Sheet!$B$4:$F$133,4,0) -> 0 | F8: ○ | G8: =RANK(H8,$H$4:$H$37,0) -> 2 | H8: =I8+개인기록Sheet!C10 -> 8.6 | I8: =(COUNTIF(J8:CD8,"출전")*1) -> 5 | J8: 출전 | K8: 출전 | L8: 출전 | M8: 출전 | N8: 출전
A9: 6 | B9: 김기문 | C9: =VLOOKUP(B9,종합Sheet!$B$4:$F$133,2,0) -> 2022 | D9: =VLOOKUP(B9,종합Sheet!$B$4:$F$133,3,0) -> 지급 | E9: =VLOOKUP(B9,종합Sheet!$B$4:$F$133,4,0) -> 0 | F9: ○ | G9: =RANK(H9,$H$4:$H$37,0) -> 20 | H9: =I9+개인기록Sheet!C15 -> 3.6 | I9: =(COUNTIF(J9:CD9,"출전")*1) -> 3 | J9: 출전 | K9: 출전 | L9: 출전
A10: 7 | B10: 김대현 | C10: =VLOOKUP(B10,종합Sheet!$B$4:$F$133,2,0) -> #N/A | D10: =VLOOKUP(B10,종합Sheet!$B$4:$F$133,3,0) -> #N/A | E10: =VLOOKUP(B10,종합Sheet!$B$4:$F$133,4,0) -> #N/A | F10: ○ | G10: =RANK(H10,$H$4:$H$37,0) -> 7 | H10: =I10+개인기록Sheet!C16 -> 6.8 | I10: =(COUNTIF(J10:CD10,"출전")*1) -> 3 | K10: 출전 | L10: 출전 | M10: 출전
A11: 8 | B11: 김덕준 | C11: =VLOOKUP(B11,종합Sheet!$B$4:$F$133,2,0) -> 2023 | D11: =VLOOKUP(B11,종합Sheet!$B$4:$F$133,3,0) -> 지급 | E11: =VLOOKUP(B11,종합Sheet!$B$4:$F$133,4,0) -> 0 | F11: ○ | G11: =RANK(H11,$H$4:$H$37,0) -> 5 | H11: =I11+개인기록Sheet!C17 -> 7.8 | I11: =(COUNTIF(J11:CD11,"출전")*1) -> 4 | K11: 출전 | L11: 출전 | N11: 출전 | O11: 출전
A12: 9 | B12: 김동인 | C12: =VLOOKUP(B12,종합Sheet!$B$4:$F$133,2,0) -> #N/A | D12: =VLOOKUP(B12,종합Sheet!$B$4:$F$133,3,0) -> #N/A | E12: =VLOOKUP(B12,종합Sheet!$B$4:$F$133,4,0) -> #N/A | F12: ○ | G12: =RANK(H12,$H$4:$H$37,0) -> 24 | H12: =I12+개인기록Sheet!C18 -> 3 | I12: =(COUNTIF(J12:CD12,"출전")*1) -> 3 | K12: 출전 | L12: 출전 | O12: 출전
A13: 10 | B13: 김부건 | C13: =VLOOKUP(B13,종합Sheet!$B$4:$F$133,2,0) -> Origin | D13: =VLOOKUP(B13,종합Sheet!$B$4:$F$133,3,0) -> 지급 | E13: =VLOOKUP(B13,종합Sheet!$B$4:$F$133,4,0) -> 0 | F13: ○ | G13: =RANK(H13,$H$4:$H$37,0) -> 26 | H13: =I13+개인기록Sheet!C22 -> 2 | I13: =(COUNTIF(J13:CD13,"출전")*1) -> 2 | K13: 출전 | N13: 출전
A14: 11 | B14: 김성수 | C14: =VLOOKUP(B14,종합Sheet!$B$4:$F$133,2,0) -> 2023 | D14: =VLOOKUP(B14,종합Sheet!$B$4:$F$133,3,0) -> 지급 | E14: =VLOOKUP(B14,종합Sheet!$B$4:$F$133,4,0) -> 0 | F14: ○ | G14: =RANK(H14,$H$4:$H$37,0) -> 29 | H14: =I14+개인기록Sheet!C23 -> 1 | I14: =(COUNTIF(J14:CD14,"출전")*1) -> 1 | J14: 출전
A15: 12 | B15: 김성준 | C15: =VLOOKUP(B15,종합Sheet!$B$4:$F$133,2,0) -> 2024 | D15: =VLOOKUP(B15,종합Sheet!$B$4:$F$133,3,0) -> 지급 | E15: =VLOOKUP(B15,종합Sheet!$B$4:$F$133,4,0) -> 0 | O15: 출전
A16: 13 | B16: 김송환 | C16: =VLOOKUP(B16,종합Sheet!$B$4:$F$133,2,0) -> Origin | D16: =VLOOKUP(B16,종합Sheet!$B$4:$F$133,3,0) -> 지급 | E16: =VLOOKUP(B16,종합Sheet!$B$4:$F$133,4,0) -> 0 | F16: ○ | G16: =RANK(H16,$H$4:$H$37,0) -> 4 | H16: =I16+개인기록Sheet!C25 -> 7.9 | I16: =(COUNTIF(J16:CD16,"출전")*1) -> 5 | J16: 출전 | K16: 출전 | L16: 출전 | N16: 출전 | O16: 출전
A17: 14 | B17: 김영태 | C17: =VLOOKUP(B17,종합Sheet!$B$4:$F$133,2,0) -> 2023 | D17: =VLOOKUP(B17,종합Sheet!$B$4:$F$133,3,0) -> 0 | E17: =VLOOKUP(B17,종합Sheet!$B$4:$F$133,4,0) -> 0 | F17: ○ | G17: =RANK(H17,$H$4:$H$37,0) -> 1 | H17: =I17+개인기록Sheet!C26 -> 11.7 | I17: =(COUNTIF(J17:CD17,"출전")*1) -> 1 | M17: 출전
A18: 15 | B18: 김용현 | C18: =VLOOKUP(B18,종합Sheet!$B$4:$F$133,2,0) -> Origin | D18: =VLOOKUP(B18,종합Sheet!$B$4:$F$133,3,0) -> 지급 | E18: =VLOOKUP(B18,종합Sheet!$B$4:$F$133,4,0) -> 0 | F18: ○ | G18: =RANK(H18,$H$4:$H$37,0) -> 13 | H18: =I18+개인기록Sheet!C29 -> 5 | I18: =(COUNTIF(J18:CD18,"출전")*1) -> 5 | J18: 출전 | L18: 출전 | M18: 출전 | N18: 출전 | O18: 출전
A19: 16 | B19: 김종준 | C19: =VLOOKUP(B19,종합Sheet!$B$4:$F$133,2,0) -> Origin | D19: =VLOOKUP(B19,종합Sheet!$B$4:$F$133,3,0) -> 지급 | E19: =VLOOKUP(B19,종합Sheet!$B$4:$F$133,4,0) -> 0 | F19: ○ | G19: =RANK(H19,$H$4:$H$37,0) -> 13 | H19: =I19+개인기록Sheet!C34 -> 5 | I19: =(COUNTIF(J19:CD19,"출전")*1) -> 5 | J19: 출전 | K19: 출전 | L19: 출전 | M19: 출전 | O19: 출전
A20: 17 | B20: 김형원 | C20: =VLOOKUP(B20,종합Sheet!$B$4:$F$133,2,0) -> 2022 | D20: =VLOOKUP(B20,종합Sheet!$B$4:$F$133,3,0) -> 지급 | E20: =VLOOKUP(B20,종합Sheet!$B$4:$F$133,4,0) -> 0 | F20: ○ | G20: =RANK(H20,$H$4:$H$37,0) -> 26 | H20: =I20+개인기록Sheet!C40 -> 2 | I20: =(COUNTIF(J20:CD20,"출전")*1) -> 2 | J20: 출전 | O20: 출전
A21: 18 | B21: 문준수 | C21: =VLOOKUP(B21,종합Sheet!$B$4:$F$133,2,0) -> 2022 | D21: =VLOOKUP(B21,종합Sheet!$B$4:$F$133,3,0) -> 지급 | E21: =VLOOKUP(B21,종합Sheet!$B$4:$F$133,4,0) -> 0 | F21: ○ | G21: =RANK(H21,$H$4:$H$37,0) -> 10 | H21: =I21+개인기록Sheet!C44 -> 5.6 | I21: =(COUNTIF(J21:CD21,"출전")*1) -> 2 | M21: 출전 | O21: 출전
A22: 19 | B22: 민건호 | C22: =VLOOKUP(B22,종합Sheet!$B$4:$F$133,2,0) -> 2022 | D22: =VLOOKUP(B22,종합Sheet!$B$4:$F$133,3,0) -> 3 | E22: =VLOOKUP(B22,종합Sheet!$B$4:$F$133,4,0) -> 0 | O22: 출전
A23: 20 | B23: 박주연 | C23: =VLOOKUP(B23,종합Sheet!$B$4:$F$133,2,0) -> 2023 | D23: =VLOOKUP(B23,종합Sheet!$B$4:$F$133,3,0) -> 지급 | E23: =VLOOKUP(B23,종합Sheet!$B$4:$F$133,4,0) -> 0 | F23: ○ | G23: =RANK(H23,$H$4:$H$37,0) -> 18 | H23: =I23+개인기록Sheet!C49 -> 4 | I23: =(COUNTIF(J23:CD23,"출전")*1) -> 4 | K23: 출전 | L23: 출전 | N23: 출전 | O23: 출전
A24: 21 | B24: 오우영 | C24: =VLOOKUP(B24,종합Sheet!$B$4:$F$133,2,0) -> 2022 | D24: =VLOOKUP(B24,종합Sheet!$B$4:$F$133,3,0) -> 지급 | E24: =VLOOKUP(B24,종합Sheet!$B$4:$F$133,4,0) -> 0 | F24: ○ | G24: =RANK(H24,$H$4:$H$37,0) -> 23 | H24: =I24+개인기록Sheet!C57 -> 3.2 | I24: =(COUNTIF(J24:CD24,"출전")*1) -> 2 | M24: 출전 | N24: 출전
A25: 22 | B25: 유인상 | C25: =VLOOKUP(B25,종합Sheet!$B$4:$F$133,2,0) -> 2023 | D25: =VLOOKUP(B25,종합Sheet!$B$4:$F$133,3,0) -> 지급 | E25: =VLOOKUP(B25,종합Sheet!$B$4:$F$133,4,0) -> 0 | F25: ○ | G25: =RANK(H25,$H$4:$H$37,0) -> 24 | H25: =I25+개인기록Sheet!C59 -> 3 | I25: =(COUNTIF(J25:CD25,"출전")*1) -> 3 | J25: 출전 | N25: 출전 | O25: 출전
A26: 23 | B26: 유정훈 | C26: =VLOOKUP(B26,종합Sheet!$B$4:$F$133,2,0) -> 2021 | D26: =VLOOKUP(B26,종합Sheet!$B$4:$F$133,3,0) -> 지급 | E26: =VLOOKUP(B26,종합Sheet!$B$4:$F$133,4,0) -> 0 | F26: ○ | G26: =RANK(H26,$H$4:$H$37,0) -> 15 | H26: =I26+개인기록Sheet!C60 -> 4.8 | I26: =(COUNTIF(J26:CD26,"출전")*1) -> 4 | J26: 출전 | K26: 출전 | M26: 출전 | N26: 출전
A27: 24 | B27: 윤성용 | C27: =VLOOKUP(B27,종합Sheet!$B$4:$F$133,2,0) -> #N/A | D27: =VLOOKUP(B27,종합Sheet!$B$4:$F$133,3,0) -> #N/A | E27: =VLOOKUP(B27,종합Sheet!$B$4:$F$133,4,0) -> #N/A | F27: ○ | G27: =RANK(H27,$H$4:$H$37,0) -> 8 | H27: =I27+개인기록Sheet!C62 -> 6.7 | I27: =(COUNTIF(J27:CD27,"출전")*1) -> 3 | L27: 출전 | M27: 출전 | O27: 출전
A28: 25 | B28: 윤창현 | C28: =VLOOKUP(B28,종합Sheet!$B$4:$F$133,2,0) -> Origin | D28: =VLOOKUP(B28,종합Sheet!$B$4:$F$133,3,0) -> 지급 | E28: =VLOOKUP(B28,종합Sheet!$B$4:$F$133,4,0) -> 0 | F28: ○ | G28: =RANK(H28,$H$4:$H$37,0) -> 22 | H28: =I28+개인기록Sheet!C63 -> 3.3 | I28: =(COUNTIF(J28:CD28,"출전")*1) -> 3 | K28: 출전 | M28: 출전 | N28: 출전
A29: 26 | B29: 이상민 | C29: =VLOOKUP(B29,종합Sheet!$B$4:$F$133,2,0) -> 2023 | D29: =VLOOKUP(B29,종합Sheet!$B$4:$F$133,3,0) -> 지급 | E29: =VLOOKUP(B29,종합Sheet!$B$4:$F$133,4,0) -> 0 | F29: ○ | G29: =RANK(H29,$H$4:$H$37,0) -> 19 | H29: =I29+개인기록Sheet!C64 -> 3.9 | I29: =(COUNTIF(J29:CD29,"출전")*1) -> 1 | N29: 출전
A30: 27 | B30: 이상현 | C30: =VLOOKUP(B30,종합Sheet!$B$4:$F$133,2,0) -> Origin | D30: =VLOOKUP(B30,종합Sheet!$B$4:$F$133,3,0) -> 지급 | E30: =VLOOKUP(B30,종합Sheet!$B$4:$F$133,4,0) -> 0 | F30: ○ | G30: =RANK(H30,$H$4:$H$37,0) -> 21 | H30: =I30+개인기록Sheet!C69 -> 3.4 | I30: =(COUNTIF(J30:CD30,"출전")*1) -> 3 | L30: 출전 | M30: 출전 | N30: 출전
A31: 28 | B31: 이연길 | C31: =VLOOKUP(B31,종합Sheet!$B$4:$F$133,2,0) -> Origin | D31: =VLOOKUP(B31,종합Sheet!$B$4:$F$133,3,0) -> 지급 | E31: =VLOOKUP(B31,종합Sheet!$B$4:$F$133,4,0) -> 0 | F31: ○ | G31: =RANK(H31,$H$4:$H$37,0) -> 29 | H31: =I31+개인기록Sheet!C72 -> 1 | I31: =(COUNTIF(J31:CD31,"출전")*1) -> 1 | M31: 출전
A32: 29 | B32: 임호연 | C32: =VLOOKUP(B32,종합Sheet!$B$4:$F$133,2,0) -> #N/A | D32: =VLOOKUP(B32,종합Sheet!$B$4:$F$133,3,0) -> #N/A | E32: =VLOOKUP(B32,종합Sheet!$B$4:$F$133,4,0) -> #N/A | F32: ○ | G32: =RANK(H32,$H$4:$H$37,0) -> 12 | H32: =I32+개인기록Sheet!C79 -> 5.2 | I32: =(COUNTIF(J32:CD32,"출전")*1) -> 4 | J32: 출전 | K32: 출전 | L32: 출전 | O32: 출전
A33: 30 | B33: 전성환 | C33: =VLOOKUP(B33,종합Sheet!$B$4:$F$133,2,0) -> 2022 | D33: =VLOOKUP(B33,종합Sheet!$B$4:$F$133,3,0) -> 0 | E33: =VLOOKUP(B33,종합Sheet!$B$4:$F$133,4,0) -> 0 | F33: ○ | G33: =RANK(H33,$H$4:$H$37,0) -> 17 | H33: =I33+개인기록Sheet!C83 -> 4.2 | I33: =(COUNTIF(J33:CD33,"출전")*1) -> 1 | M33: 출전
A34: 31 | B34: 차승원 | C34: =VLOOKUP(B34,종합Sheet!$B$4:$F$133,2,0) -> 2023 | D34: =VLOOKUP(B34,종합Sheet!$B$4:$F$133,3,0) -> 지급 | E34: =VLOOKUP(B34,종합Sheet!$B$4:$F$133,4,0) -> 0 | F34: ○ | G34: =RANK(H34,$H$4:$H$37,0) -> 29 | H34: =I34+개인기록Sheet!C90 -> 1 | I34: =(COUNTIF(J34:CD34,"출전")*1) -> 1 | K34: 출전
A35: 32 | B35: 황석원 | C35: =VLOOKUP(B35,종합Sheet!$B$4:$F$133,2,0) -> 2023 | D35: =VLOOKUP(B35,종합Sheet!$B$4:$F$133,3,0) -> 지급 | E35: =VLOOKUP(B35,종합Sheet!$B$4:$F$133,4,0) -> 0 | F35: ○ | G35: =RANK(H35,$H$4:$H$37,0) -> 6 | H35: =I35+개인기록Sheet!C97 -> 7.7 | I35: =(COUNTIF(J35:CD35,"출전")*1) -> 5 | J35: 출전 | K35: 출전 | L35: 출전 | M35: 출전 | O35: 출전
A36: 33 | B36: 김민성 | C36: =VLOOKUP(B36,종합Sheet!$B$4:$F$133,2,0) -> Origin | D36: =VLOOKUP(B36,종합Sheet!$B$4:$F$133,3,0) -> 지급 | E36: =VLOOKUP(B36,종합Sheet!$B$4:$F$133,4,0) -> 0 | F36: ○ | G36: =RANK(H36,$H$4:$H$37,0) -> 16 | H36: =I36+개인기록Sheet!C102 -> 4.7 | I36: =(COUNTIF(J36:CD36,"출전")*1) -> 3 | J36: 출전 | K36: 출전 | L36: 출전
A37: 34 | B37: 최경영 | C37: =VLOOKUP(B37,종합Sheet!$B$4:$F$133,2,0) -> Origin | D37: =VLOOKUP(B37,종합Sheet!$B$4:$F$133,3,0) -> 지급 | E37: =VLOOKUP(B37,종합Sheet!$B$4:$F$133,4,0) -> 0 | F37: ○ | G37: =RANK(H37,$H$4:$H$37,0) -> 3 | H37: =I37+개인기록Sheet!C104 -> 8.2 | I37: =(COUNTIF(J37:CD37,"출전")*1) -> 5 | J37: 출전 | K37: 출전 | L37: 출전 | N37: 출전 | O37: 출전

Sheet 경기기록Sheet (외부)
B2: MATCH
B4: 44985 | C4: 김청축 | D4: Semi-Pro | E4: Goal | I4: Assist | M4: Balance | Q4: Clean Sheet
B5: 1Q | C5: 2 | D5: 0 | E5: 김동인 | F5: 강기혁 | J5: 유정훈 | M5: 신재경 | N5: 김송환 | O5: 김기문 | Q5: 김덕준 | R5: 황석원 | S5: 김종준 | T5: 유정훈 | V5: 최경영
B6: 2Q | C6: 2 | D6: 1 | E6: 김민성 | F6: OG | I6: 김대현
B7: 3Q | C7: 0 | D7: 2
B8: 4Q | C8: 1 | D8: 0 | E8: 신재경 | M8: 신재경 | N8: 김송환 | O8: 김기문 | P8: 김동인 | Q8: 김덕준 | R8: 황석원 | S8: 차승원 | T8: 박주연 | V8: 최경영
B9: 5Q
B10: Total | C10: =SUM(C5:C9) -> 5 | D10: =SUM(D5:D9) -> 3
B12: 45068 | C12: 김청축 | D12: Semi-Pro | E12: Goal | I12: Assist | M12: Balance | Q12: Clean Sheet
B13: 1Q | C13: 1 | D13: 0 | E13: 강기혁 | M13: 신재경 | N13: 유정훈 | O13: 이상현 | Q13: 문준수 | R13: 황석원 | S13: 윤성용 | T13: 윤창현 | V13: 김영태
B14: 2Q | C14: 3 | D14: 0 | E14: 유정훈 | F14: 유정훈 | G14: 강기혁 | I14: 신재경 | M14: 김용현 | N14: 유정훈 | O14: 신재경 | Q14: 이연길 | R14: 윤성용 | S14: 김종준 | T14: 윤창현 | V14: 김영태
B15: 3Q | C15: 2 | D15: 0 | E15: 김대현 | F15: 김대현 | M15: 김용현 | N15: 이상현 | O15: 윤성용 | Q15: 문준수 | R15: 황석원 | S15: 김종준 | T15: 윤창현 | V15: 김영태
B16: 4Q | C16: 1 | D16: 0 | E16: 전성환 | I16: 유정훈
B17: 5Q
B18: Total
B20: 45074 | C20: 김청축 | D20: DS FC | E20: Goal | I20: Assist | M20: Balance | Q20: Clean Sheet
B21: 1Q | C21: 1 | D21: 0 | E21: 강기혁 | I21: 정효태 | M21: 유인상 | N21: 김송환 | O21: 유정훈 | Q21: 김덕준 | R21: 김부건 | S21: 김병문 | T21: 윤창현 | V21: 최경영
B22: 2Q | C22: 3 | D22: 0 | E22: 정효태 | F22: 강기혁 | G22: 오우영 | I22: 강기혁 | J22: 이상현 | K22: 유정훈 | M22: 이상현 | N22: 김용현 | O22: 유정훈 | Q22: 이상민 | R22: 김부건 | S22: 김병문 | T22: 윤창현 | V22: 최경영
B23: 3Q | C23: 4 | D23: 1 | E23: 이상현 | F23: 이상민 | G23: 이상현 | H23: 유인상 | I23: 이상민 | J23: 윤창현 | K23: 이상민 | L23: 윤창현
B24: 4Q | C24: 2 | D24: 1 | E24: 이상민 | F24: 이상민 | I24: 이상현 | J24: 김용현
B25: 5Q
B26: Total
